Workbook

Sheet Totals
A1: measuredWorksTotal
A2: buildingWorksEstimate
A3: totalInclRisk
A4: totalInclInflation
A5: totalInclAdjustments
A6: grandTotal

Sheet Hidden Data
O2: SPEC LEVEL
A3: BCIS Q DATE | C3: SECTOR | E3: REGION | G3: COST STAGE | K3: Complexity Rating | M3: SITE TYPE | O3: Low
A4: Q1 | C4: Residential | E4: London | G4: Cost plan | I4: Yes | M4: Brownfield | O4: Medium
A5: Q2 | C5: Student Accommodation | E5: South East | G5: Tender | I5: No | M5: Greenfield | O5: High
A6: Q3 | C6: Care Homes | E6: South West | G6: Contract Sum | O6: COMPLEXITY RATING
A7: Q4 | C7: Offices | E7: East of England | G7: Final Account | O7: 1
C8: Retail | E8: East Midlands | O8: 2
C9: Hotels | E9: West Midlands | O9: 3
C10: Leisure Facilities | E10: North West | O10: 4
C11: Warehouses | E11: North East | O11: 5
C12: Civils | E12: Yorkshire and the Humber | K12: USD
C13: Schools | E13: Scotland | K13: GBP
C14: Universities | E14: Wales | K14: EURO
C15: Hospitals | E15: Northern Ireland
C16: Medical Centres
C17: Laboratories
C18: Heritage
C19: Data Centres

Sheet Project Information - 1
A1: Key Data
A2: Project Name * | B2: Elm Court Residential
A3: Project Number * | B3: DEMO-2026-001
A4: Report date * | B4: 46093
A5: Base Date * | B5: 46093
A6: BCIS Q Date * | B6: Q2
A7: Sector * | B7: Residential
A8: Location * | B8: London
A9: Currency * | B9: GBP
A10: Programme (weeks) | B10: 52
A11: Project Type - New Build * | B11: Yes
A12: Project Type - Horizontal extension* | B12: No
A13: Project Type - Vertical extension* | B13: No
A14: Project Type - Refurbishment* | B14: No
A15: Spec Level | B15: Low
A16: Cost Stage* | B16: Cost plan
A17: Inflation adjusted* | B17: Yes
A18: Region adjusted* | B18: Yes
A19: Prelims included?* | B19: Yes
A20: Prof fees included?* | B20: No
A21: Site Type* | B21: Brownfield
A22: Access Constraints | B22: Restricted site access via single road frontage
A23: Complexity Rating | B23: 3
A24: Nr of Storeys * | B24: 4
A25: Basement * | B25: Yes
A26: Occupied? * | B26: No
A29: Costplan Document
A30: Reference for Costplan Budget Document * | B30: Sample Cost Plan - Elm Court Residential, Rev 01 | C30: Costplan document to include date and revision.
A32: Tendering Contractors
A33: Contractor 1 (SELECTED CONTRACTOR) * | B33: Ridgeway Construction
A34: Contractor 2 | B34: Brightstone Builders
A35: Contractor 3 | B35: Kestrel Contractors
A36: Contractor 4 | B36: INSERT CONTRACTOR 4
A37: Contractor 5 | B37: INSERT CONTRACTOR 5
A38: Contractor 6 | B38: INSERT CONTRACTOR 6
A39: Contractor 7 | B39: INSERT CONTRACTOR 7
A42: Benchmark Projects
A43: Benchmark 1 | B43: INSERT BENCHMARK NAME
A44: Benchmark 2 | B44: INSERT BENCHMARK NAME

Sheet Project Information - 2
A1: Name | B1: Qty | C1: Unit | D1: Comments
A2: GIFA * | B2: 1001 | C2: m2
A12: SECTOR
A13: Residential
A14: flats | B14: 18 | C14: nr
A15: houses | B15: 4 | C15: nr
A16: total plots | B16: 22 | C16: nr
A18: Student Accommodation
A19: Care Homes
A20: Offices
A21: Retail
A23: Hotels
A24: Keys | B24: 7 | C24: nr
A25: FoH Area | B25: 951 | C25: m2
A26: BoH Area | B26: 50 | C26: m2
A28: Leisure Facilities
A29: Warehouses
A30: Civils
A31: Schools
A32: Universities
A33: Hospitals
A34: Medical Centres
A35: Laboratories
A36: Heritage
A37: Data Centres

Sheet Project Information - 3
A1: Code | B1: Element | C1: Qty | D1: Unit | E1: Comments
A2: 0.1 | B2: Demolition and alterations | C2: 503 | D2: m2 | E2: GIFA of buildings to be demolished
B3: Groundworks (cut and fill) | C3: 0 | D3: m2 | E3: Site Area
B4: Ground Remediation Works | C4: 0 | D4: m2 | E4: Site Area
A5: =INDEX(SUMMARY!$A$8:$A$52,MATCH(B5,SUMMARY!$B$8:$B$52,0)) -> 1.1 | B5: Substructure | C5: 393 | D5: m2
A6: =INDEX(SUMMARY!$A$5:$A$52,MATCH(B6,SUMMARY!$B$5:$B$52,0)) -> 2.1 | B6: Frame | C6: 960 | D6: m2
A7: =INDEX(SUMMARY!$A$5:$A$52,MATCH(B7,SUMMARY!$B$5:$B$52,0)) -> 2.2 | B7: Upper Floors | C7: 686 | D7: m2
A8: =INDEX(SUMMARY!$A$5:$A$52,MATCH(B8,SUMMARY!$B$5:$B$52,0)) -> 2.3 | B8: Roof | C8: 271 | D8: m2
A9: =INDEX(SUMMARY!$A$5:$A$52,MATCH(B9,SUMMARY!$B$5:$B$52,0)) -> 2.4 | B9: Stairs and Ramps | C9: 8 | D9: no
A10: =INDEX(SUMMARY!$A$5:$A$52,MATCH(B10,SUMMARY!$B$5:$B$52,0)) -> 2.5 | B10: External Walls | C10: 581 | D10: m2
A11: =INDEX(SUMMARY!$A$5:$A$52,MATCH(B11,SUMMARY!$B$5:$B$52,0)) -> 2.6 | B11: Windows & External Doors | C11: 203 | D11: m2
A12: =INDEX(SUMMARY!$A$5:$A$52,MATCH(B12,SUMMARY!$B$5:$B$52,0)) -> 2.7 | B12: Internal Walls and Partitions | C12: 902 | D12: m2
A13: =INDEX(SUMMARY!$A$5:$A$52,MATCH(B13,SUMMARY!$B$5:$B$52,0)) -> 2.8 | B13: Internal Doors | C13: 77 | D13: no/leaf
A14: =INDEX(SUMMARY!$A$5:$A$52,MATCH(B14,SUMMARY!$B$5:$B$52,0)) -> 3.1 | B14: Wall finishes | C14: 3183 | D14: m2
A15: =INDEX(SUMMARY!$A$5:$A$52,MATCH(B15,SUMMARY!$B$5:$B$52,0)) -> 3.2 | B15: Floor finishes | C15: 907 | D15: m2
A16: =INDEX(SUMMARY!$A$5:$A$52,MATCH(B16,SUMMARY!$B$5:$B$52,0)) -> 3.3 | B16: Ceiling finishes | C16: 881 | D16: m2
A17: =SUMMARY!$A$23 -> 4.1 | B17: Fittings Furnishings and Equipment | C17: 1 | D17: m2
A18: =INDEX(SUMMARY!$A$5:$A$52,MATCH(B18,SUMMARY!$B$5:$B$52,0)) -> 5.1 | B18: Sanitary installations | C18: 1 | D18: m2
A19: =INDEX(SUMMARY!$A$5:$A$52,MATCH(B19,SUMMARY!$B$5:$B$52,0)) -> 5.2 | B19: Services Equipment | C19: 1 | D19: m2
A20: =INDEX(SUMMARY!$A$5:$A$52,MATCH(B20,SUMMARY!$B$5:$B$52,0)) -> 5.3 | B20: Electrical Installations | C20: 1 | D20: m2
A21: =INDEX(SUMMARY!$A$5:$A$52,MATCH(B21,SUMMARY!$B$5:$B$52,0)) -> 5.4 | B21: Mechanical Installations | C21: 1 | D21: m2
A22: =INDEX(SUMMARY!$A$5:$A$52,MATCH(B22,SUMMARY!$B$5:$B$52,0)) -> 5.5 | B22: Lift and conveyor installations | C22: 1 | D22: nr
A23: =INDEX(SUMMARY!$A$5:$A$52,MATCH(B23,SUMMARY!$B$5:$B$52,0)) -> 5.6 | B23: Fire and lightning protection | C23: 1 | D23: m2
A24: =INDEX(SUMMARY!$A$5:$A$52,MATCH(B24,SUMMARY!$B$5:$B$52,0)) -> 5.7 | B24: Communication, security and control systems | C24: 1 | D24: m2
A25: =INDEX(SUMMARY!$A$5:$A$52,MATCH(B25,SUMMARY!$B$5:$B$52,0)) -> 5.8 | B25: Specialist installations | C25: 1 | D25: m2
A26: =INDEX(SUMMARY!$A$5:$A$52,MATCH(B26,SUMMARY!$B$5:$B$52,0)) -> 5.9 | B26: BWIC with services | C26: 1 | D26: m2
A27: =INDEX(SUMMARY!$A$5:$A$52,MATCH(B27,SUMMARY!$B$5:$B$52,0)) -> 5.1 | B27: Testing and commissioning of services | C27: 1 | D27: m2
A28: =INDEX(SUMMARY!$A$36:$A$52,MATCH(B28,SUMMARY!$B$36:$B$52,0)) -> 6.1 | B28: Prefabricated buildings and building units | C28: 1000 | D28: m2
A29: =INDEX(SUMMARY!$A$5:$A$52,MATCH(B29,SUMMARY!$B$5:$B$52,0)) -> 7.1 | B29: Minor demolition and alteration works | C29: 1000 | D29: m2
A30: =INDEX(SUMMARY!$A$5:$A$52,MATCH(B30,SUMMARY!$B$5:$B$52,0)) -> 7.2 | B30: repairs to existing services | C30: 1000 | D30: m2
A31: =INDEX(SUMMARY!$A$5:$A$52,MATCH(B31,SUMMARY!$B$5:$B$52,0)) -> 7.3 | B31: Damp proof courses / fungus and beetle eradication | C31: 1000 | D31: m2
A32: =INDEX(SUMMARY!$A$5:$A$52,MATCH(B32,SUMMARY!$B$5:$B$52,0)) -> 7.4 | B32: Façade retention | C32: 1000 | D32: m2
A33: =INDEX(SUMMARY!$A$5:$A$52,MATCH(B33,SUMMARY!$B$5:$B$52,0)) -> 7.5 | B33: Cleaning existing surfaces | C33: 1000 | D33: m2
A34: =INDEX(SUMMARY!$A$5:$A$52,MATCH(B34,SUMMARY!$B$5:$B$52,0)) -> 7.6 | B34: Renovation works | C34: 1000 | D34: m2
A35: =INDEX(SUMMARY!$A$5:$A$52,MATCH(B35,SUMMARY!$B$5:$B$52,0)) -> 8.1 | B35: Site preparation works | C35: 1000 | D35: m2
A36: =INDEX(SUMMARY!$A$5:$A$52,MATCH(B36,SUMMARY!$B$5:$B$52,0)) -> 8.2 | B36: Roads, paths, pavings and surfacings | C36: 1000 | D36: m2
A37: =INDEX(SUMMARY!$A$5:$A$52,MATCH(B37,SUMMARY!$B$5:$B$52,0)) -> 8.3 | B37: Soft landscapes, planting and irrigation systems | C37: 1000 | D37: m2
A38: =INDEX(SUMMARY!$A$5:$A$52,MATCH(B38,SUMMARY!$B$5:$B$52,0)) -> 8.4 | B38: Fencing, railings and walls | C38: 1000 | D38: m2
A39: =INDEX(SUMMARY!$A$5:$A$52,MATCH(B39,SUMMARY!$B$5:$B$52,0)) -> 8.5 | B39: External fixtures | C39: 1000 | D39: m2
A40: =INDEX(SUMMARY!$A$5:$A$52,MATCH(B40,SUMMARY!$B$5:$B$52,0)) -> 8.6 | B40: External drainage | C40: 1000 | D40: m2
...

Sheet SUMMARY
E3: ='Project Information - 1'!B30 -> Sample Cost Plan - Elm Court Residential, Rev 01 | H3: Average Tender | K3: ='Project Information - 1'!B33 -> Ridgeway Construction | N3: ='Project Information - 1'!B34 -> Brightstone Builders | Q3: ='Project Information - 1'!B35 -> Kestrel Contractors | T3: ='Project Information - 1'!B36 -> INSERT CONTRACTOR 4 | W3: ='Project Information - 1'!B37 -> INSERT CONTRACTOR 5 | Z3: ='Project Information - 1'!B38 -> INSERT CONTRACTOR 6 | AC3: ='Project Information - 1'!B39 -> INSERT CONTRACTOR 7 | AF3: ='Project Information - 1'!B43 -> INSERT BENCHMARK NAME | AI3: ='Project Information - 1'!B44 -> INSERT BENCHMARK NAME | AL3: Limit 1 | AN3: Limit 2
A4: Code | B4: Element | C4: EUQ | D4: Unit | E4: EUR | F4: Total | H4: EUR | I4: Total | K4: EUR | L4: Total | N4: EUR | O4: Total | Q4: EUR | R4: Total | T4: EUR | U4: Total | W4: EUR | X4: Total | Z4: EUR | AA4: Total | AC4: EUR | AD4: Total | AF4: EUR | AG4: Total | AI4: EUR | AJ4: Total | AL4: Lower bound | AM4: Upper Bound | AN4: Lower bound | AO4: Upper Bound
A5: 0 | B5: Facilitating Works | F5: =SUBTOTAL(9,F6:F6) -> 430551.5 | I5: =SUBTOTAL(9,I6:I6) -> 270028 | L5: =SUBTOTAL(9,L6:L6) -> 430551.5 | O5: =SUBTOTAL(9,O6:O6) -> 195746 | R5: =SUBTOTAL(9,R6:R6) -> 183786.5 | U5: =SUBTOTAL(9,U6:U6) -> 198451.5 | X5: =SUBTOTAL(9,X6:X6) -> 0 | AA5: =SUBTOTAL(9,AA6:AA6) -> 0 | AD5: =SUBTOTAL(9,AD6:AD6) -> 0 | AG5: =SUBTOTAL(9,AG6) -> 0 | AJ5: =SUBTOTAL(9,AJ6) -> 0
A6: 0.1 | B6: Demolition and alterations | C6: ='Project Information - 3'!$C$2 -> 503 | D6: m2 | E6: =SUM(F6)/$C6 -> 855.9672 | F6: ='0.1 Demolition & alterations'!F54 -> 430551.5 | H6: =SUM(I6)/$C6 -> 536.83499 | I6: =AVERAGE(L6,O6,R6) -> 270028 | L6: ='0.1 Demolition & alterations'!F54 -> 430551.5 | O6: ='0.1 Demolition & alterations'!K54 -> 195746 | R6: ='0.1 Demolition & alterations'!P54 -> 183786.5 | U6: ='0.1 Demolition & alterations'!U54 -> 198451.5
A7: 1 | B7: Substructure | F7: =SUBTOTAL(9,F8:F8) -> 153205 | I7: =SUBTOTAL(9,I8:I8) -> 130593 | L7: =SUBTOTAL(9,L8:L8) -> 108987 | O7: =SUBTOTAL(9,O8:O8) -> 172205 | R7: =SUBTOTAL(9,R8:R8) -> 110587 | U7: =SUBTOTAL(9,U8:U8) -> 0 | X7: =SUBTOTAL(9,X8:X8) -> 0 | AA7: =SUBTOTAL(9,AA8:AA8) -> 0 | AD7: =SUBTOTAL(9,AD8:AD8) -> 0 | AG7: =SUBTOTAL(9,AG8:AG8) -> 0 | AJ7: =SUBTOTAL(9,AJ8:AJ8) -> 0
A8: 1.1 | B8: Substructure | C8: ='Project Information - 3'!$C$5 -> 393 | D8: m2 | E8: =SUM(F8)/$C8 -> 389.83461 | F8: ='1.1 Substructure'!F54 -> 153205 | H8: =SUM(I8)/$C8 -> 332.29771 | I8: =AVERAGE(L8,O8,R8) -> 130593 | K8: =SUM(L8)/$C8 -> 277.32061 | L8: ='1.1 Substructure'!K54 -> 108987 | N8: =SUM(O8)/$C8 -> 438.18066 | O8: ='1.1 Substructure'!P54 -> 172205 | Q8: =SUM(R8)/$C8 -> 281.39186 | R8: ='1.1 Substructure'!U54 -> 110587 | T8: =SUM(U8)/$C8 -> 0 | U8: ='1.1 Substructure'!Z54 -> 0 | W8: =SUM(X8)/$C8 -> 0 | X8: ='1.1 Substructure'!AE54 -> 0 | Z8: =SUM(AA8)/$C8 -> 0 | AA8: ='1.1 Substructure'!AJ54 -> 0 | AC8: =SUM(AD8)/$C8 -> 0 | AD8: ='1.1 Substructure'!AO54 -> 0 | AF8: =SUM(AG8)/$C8 -> 0 | AI8: =SUM(AJ8)/$C8 -> 0
A9: 2 | B9: Superstructure | F9: =SUM(F10:F17) -> 1051375 | I9: =SUM(I10:I17) -> 1051375 | L9: =SUM(L10:L17) -> 1051375 | O9: =SUM(O10:O17) -> 1051375 | R9: =SUM(R10:R17) -> 1051375 | U9: =SUM(U10:U17) -> 0 | X9: =SUM(X10:X17) -> 0 | AA9: =SUM(AA10:AA17) -> 0 | AD9: =SUM(AD10:AD17) -> 0 | AG9: =SUM(AG10:AG14) -> 0 | AI9: =AJ9/'Project Information - 1'!$G$3 -> #DIV/0! | AJ9: =SUM(AJ10:AJ14) -> 0
A10: 2.1 | B10: Frame | C10: ='Project Information - 3'!$C$6 -> 960 | D10: m2 | E10: =SUM(F10)/$C10 -> 491.64062 | F10: ='2.1 Frame'!F54 -> 471975 | H10: =SUM(I10)/$C10 -> 491.64062 | I10: =AVERAGE(L10,O10,R10) -> 471975 | K10: =SUM(L10)/$C10 -> 491.64062 | L10: ='2.1 Frame'!K54 -> 471975 | N10: =SUM(O10)/$C10 -> 491.64062 | O10: ='2.1 Frame'!P54 -> 471975 | Q10: =SUM(R10)/$C10 -> 491.64062 | R10: ='2.1 Frame'!U54 -> 471975 | T10: =SUM(U10)/$C10 -> 0 | U10: ='2.1 Frame'!Z54 -> 0 | W10: =SUM(X10)/$C10 -> 0 | X10: ='2.1 Frame'!AE54 -> 0 | Z10: =SUM(AA10)/$C10 -> 0 | AA10: ='2.1 Frame'!AJ54 -> 0 | AC10: =SUM(AD10)/$C10 -> 0 | AD10: ='2.1 Frame'!AO54 -> 0 | AF10: =SUM(AG10)/$C10 -> 0 | AI10: =SUM(AJ10)/$C10 -> 0
A11: 2.2 | B11: Upper floors | C11: ='Project Information - 3'!$C$7 -> 686 | D11: m2 | E11: =SUM(F11)/$C11 -> 525.12391 | F11: ='2.2 Upper floors'!F54 -> 360235 | H11: =SUM(I11)/$C11 -> 525.12391 | I11: =AVERAGE(L11,O11,R11) -> 360235 | K11: =SUM(L11)/$C11 -> 525.12391 | L11: ='2.2 Upper floors'!K54 -> 360235 | N11: =SUM(O11)/$C11 -> 525.12391 | O11: ='2.2 Upper floors'!P54 -> 360235 | Q11: =SUM(R11)/$C11 -> 525.12391 | R11: ='2.2 Upper floors'!U54 -> 360235 | T11: =SUM(U11)/$C11 -> 0 | U11: ='2.2 Upper floors'!Z54 -> 0 | W11: =SUM(X11)/$C11 -> 0 | X11: ='2.2 Upper floors'!AE54 -> 0 | Z11: =SUM(AA11)/$C11 -> 0 | AA11: ='2.2 Upper floors'!AJ54 -> 0 | AC11: =SUM(AD11)/$C11 -> 0 | AD11: ='2.2 Upper floors'!AO54 -> 0 | AF11: =SUM(AG11)/$C11 -> 0 | AI11: =SUM(AJ11)/$C11 -> 0
A12: 2.3 | B12: Roof | C12: ='Project Information - 3'!$C$8 -> 271 | D12: m2 | E12: =SUM(F12)/$C12 -> 184.50185 | F12: ='2.3 Roof'!F54 -> 50000 | H12: =SUM(I12)/$C12 -> 184.50185 | I12: =AVERAGE(L12,O12,R12) -> 50000 | K12: =SUM(L12)/$C12 -> 184.50185 | L12: ='2.3 Roof'!K54 -> 50000 | N12: =SUM(O12)/$C12 -> 184.50185 | O12: ='2.3 Roof'!P54 -> 50000 | Q12: =SUM(R12)/$C12 -> 184.50185 | R12: ='2.3 Roof'!U54 -> 50000 | T12: =SUM(U12)/$C12 -> 0 | U12: ='2.3 Roof'!Z54 -> 0 | W12: =SUM(X12)/$C12 -> 0 | X12: ='2.3 Roof'!AE54 -> 0 | Z12: =SUM(AA12)/$C12 -> 0 | AA12: ='2.3 Roof'!AJ54 -> 0 | AC12: =SUM(AD12)/$C12 -> 0 | AD12: ='2.3 Roof'!AO54 -> 0 | AF12: =SUM(AG12)/$C12 -> 0 | AI12: =SUM(AJ12)/$C12 -> 0
A13: 2.4 | B13: Stairs and Ramps | C13: ='Project Information - 3'!$C$9 -> 8 | D13: no | E13: =SUM(F13)/$C13 -> 2500 | F13: ='2.4 Stairs and Ramps'!F54 -> 20000 | H13: =SUM(I13)/$C13 -> 2500 | I13: =AVERAGE(L13,O13,R13) -> 20000 | K13: =SUM(L13)/$C13 -> 2500 | L13: ='2.4 Stairs and Ramps'!K54 -> 20000 | N13: =SUM(O13)/$C13 -> 2500 | O13: ='2.4 Stairs and Ramps'!P54 -> 20000 | Q13: =SUM(R13)/$C13 -> 2500 | R13: ='2.4 Stairs and Ramps'!U54 -> 20000 | T13: =SUM(U13)/$C13 -> 0 | U13: ='2.4 Stairs and Ramps'!Z54 -> 0 | W13: =SUM(X13)/$C13 -> 0 | X13: ='2.4 Stairs and Ramps'!AE54 -> 0 | Z13: =SUM(AA13)/$C13 -> 0 | AA13: ='2.4 Stairs and Ramps'!AJ54 -> 0 | AC13: =SUM(AD13)/$C13 -> 0 | AD13: ='2.4 Stairs and Ramps'!AO54 -> 0 | AF13: =SUM(AG13)/$C13 -> 0 | AI13: =SUM(AJ13)/$C13 -> 0
A14: 2.5 | B14: External walls | C14: ='Project Information - 3'!$C$10 -> 581 | D14: m2 | E14: =SUM(F14)/$C14 -> 33.562823 | F14: ='2.5 External walls'!F55 -> 19500 | H14: =SUM(I14)/$C14 -> 33.562823 | I14: =AVERAGE(L14,O14,R14) -> 19500 | K14: =SUM(L14)/$C14 -> 33.562823 | L14: ='2.5 External walls'!K55 -> 19500 | N14: =SUM(O14)/$C14 -> 33.562823 | O14: ='2.5 External walls'!P55 -> 19500 | Q14: =SUM(R14)/$C14 -> 33.562823 | R14: ='2.5 External walls'!U55 -> 19500 | T14: =SUM(U14)/$C14 -> 0 | U14: ='2.5 External walls'!Z55 -> 0 | W14: =SUM(X14)/$C14 -> 0 | X14: ='2.5 External walls'!AE55 -> 0 | Z14: =SUM(AA14)/$C14 -> 0 | AA14: ='2.5 External walls'!AJ55 -> 0 | AC14: =SUM(AD14)/$C14 -> 0 | AD14: ='2.5 External walls'!AO55 -> 0 | AF14: =SUM(AG14)/$C14 -> 0 | AI14: =SUM(AJ14)/$C14 -> 0
A15: 2.6 | B15: Windows & external Doors | C15: ='Project Information - 3'!$C$11 -> 203 | D15: m2 | E15: =SUM(F15)/$C15 -> 87.684729 | F15: ='2.6 Windows & external Doors'!F54 -> 17800 | H15: =SUM(I15)/$C15 -> 87.684729 | I15: =AVERAGE(L15,O15,R15) -> 17800 | K15: =SUM(L15)/$C15 -> 87.684729 | L15: ='2.6 Windows & external Doors'!K54 -> 17800 | N15: =SUM(O15)/$C15 -> 87.684729 | O15: ='2.6 Windows & external Doors'!P54 -> 17800 | Q15: =SUM(R15)/$C15 -> 87.684729 | R15: ='2.6 Windows & external Doors'!U54 -> 17800 | T15: =SUM(U15)/$C15 -> 0 | U15: ='2.6 Windows & external Doors'!Z54 -> 0 | W15: =SUM(X15)/$C15 -> 0 | X15: ='2.6 Windows & external Doors'!AE54 -> 0 | Z15: =SUM(AA15)/$C15 -> 0 | AA15: ='2.6 Windows & external Doors'!AJ54 -> 0 | AC15: =SUM(AD15)/$C15 -> 0 | AD15: ='2.6 Windows & external Doors'!AO54 -> 0 | AF15: =SUM(AG15)/$C15 -> 0 | AI15: =SUM(AJ15)/$C15 -> 0
A16: 2.7 | B16: Internal Walls and Partitions | C16: ='Project Information - 3'!$C$13 -> 77 | D16: m2 | E16: =SUM(F16)/$C16 -> 236.36364 | F16: ='2.7 Internal Walls & Partitions'!F54 -> 18200 | H16: =SUM(I16)/$C16 -> 236.36364 | I16: =AVERAGE(L16,O16,R16) -> 18200 | K16: =SUM(L16)/$C16 -> 236.36364 | L16: ='2.7 Internal Walls & Partitions'!K54 -> 18200 | N16: =SUM(O16)/$C16 -> 236.36364 | O16: ='2.7 Internal Walls & Partitions'!P54 -> 18200 | Q16: =SUM(R16)/$C16 -> 236.36364 | R16: ='2.7 Internal Walls & Partitions'!U54 -> 18200 | T16: =SUM(U16)/$C16 -> 0 | U16: ='2.7 Internal Walls & Partitions'!Z54 -> 0 | W16: =SUM(X16)/$C16 -> 0 | X16: ='2.7 Internal Walls & Partitions'!AE54 -> 0 | Z16: =SUM(AA16)/$C16 -> 0 | AA16: ='2.7 Internal Walls & Partitions'!AJ54 -> 0 | AC16: =SUM(AD16)/$C16 -> 0 | AD16: ='2.7 Internal Walls & Partitions'!AO54 -> 0 | AF16: =SUM(AG16)/$C16 -> 0 | AI16: =SUM(AJ16)/$C16 -> 0
A17: 2.8 | B17: Internal Doors | C17: ='Project Information - 3'!$C$14 -> 3183 | D17: m2 | E17: =SUM(F17)/$C17 -> 29.426642 | F17: ='2.8 Internal Doors'!F54 -> 93665 | H17: =SUM(I17)/$C17 -> 29.426642 | I17: =AVERAGE(L17,O17,R17) -> 93665 | K17: =SUM(L17)/$C17 -> 29.426642 | L17: ='2.8 Internal Doors'!K54 -> 93665 | N17: =SUM(O17)/$C17 -> 29.426642 | O17: ='2.8 Internal Doors'!P54 -> 93665 | Q17: =SUM(R17)/$C17 -> 29.426642 | R17: ='2.8 Internal Doors'!U54 -> 93665 | T17: =SUM(U17)/$C17 -> 0 | U17: ='2.8 Internal Doors'!Z54 -> 0 | W17: =SUM(X17)/$C17 -> 0 | X17: ='2.8 Internal Doors'!AE54 -> 0 | Z17: =SUM(AA17)/$C17 -> 0 | AA17: ='2.8 Internal Doors'!AJ54 -> 0 | AC17: =SUM(AD17)/$C17 -> 0 | AD17: ='2.8 Internal Doors'!AO54 -> 0 | AF17: =SUM(AG17)/$C17 -> 0 | AI17: =SUM(AJ17)/$C17 -> 0
A18: 3 | B18: Internal Finishes | F18: =SUM(F19:F21) -> 670405 | I18: =SUM(I19:I21) -> 713096.67 | L18: =SUM(L19:L21) -> 641355 | O18: =SUM(O19:O21) -> 770680 | R18: =SUM(R19:R21) -> 727255 | U18: =SUM(U19:U20) -> 0 | X18: =SUM(X19:X20) -> 0 | AA18: =SUM(AA19:AA20) -> 0 | AD18: =SUM(AD19:AD20) -> 0 | AG18: =SUM(AG19:AG20) -> 0 | AJ18: =SUM(AJ19:AJ20) -> 0
A19: 3.1 | B19: Wall finishes | C19: ='Project Information - 3'!$C$14 -> 3183 | D19: m2 | E19: =SUM(F19)/$C19 -> 51.460886 | F19: ='3.1 Wall Finishes'!F54 -> 163800 | H19: =SUM(I19)/$C19 -> 51.460886 | I19: =AVERAGE(L19,O19,R19) -> 163800 | K19: =SUM(L19)/$C19 -> 51.460886 | L19: ='3.1 Wall Finishes'!K54 -> 163800 | N19: =SUM(O19)/$C19 -> 51.460886 | O19: ='3.1 Wall Finishes'!P54 -> 163800 | Q19: =SUM(R19)/$C19 -> 51.460886 | R19: ='3.1 Wall Finishes'!U54 -> 163800 | T19: =SUM(U19)/$C19 -> 0 | U19: ='3.1 Wall Finishes'!Z54 -> 0 | W19: =SUM(X19)/$C19 -> 0 | X19: ='3.1 Wall Finishes'!AE54 -> 0 | Z19: =SUM(AA19)/$C19 -> 0 | AA19: ='3.1 Wall Finishes'!AJ54 -> 0 | AC19: =SUM(AD19)/$C19 -> 0 | AD19: ='3.1 Wall Finishes'!AO54 -> 0 | AF19: =SUM(AG19)/$C19 -> 0 | AL19: =$I19*(1-#REF!) -> #REF! | AM19: =$I19*(1+#REF!) -> #REF! | AN19: =$I19*(1-#REF!) -> #REF! | AO19: =$I19*(1+#REF!) -> #REF!
A20: 3.2 | B20: Floor finishes | C20: ='Project Information - 3'!$C$15 -> 907 | D20: m2 | E20: =SUM(F20)/$C20 -> 89.255788 | F20: ='3.2 Floor Finishes'!F54 -> 80955 | H20: =SUM(I20)/$C20 -> 89.237413 | I20: =AVERAGE(L20,O20,R20) -> 80938.333 | K20: =SUM(L20)/$C20 -> 89.807056 | L20: ='3.2 Floor Finishes'!K54 -> 81455 | N20: =SUM(O20)/$C20 -> 88.814774 | O20: ='3.2 Floor Finishes'!P54 -> 80555 | Q20: =SUM(R20)/$C20 -> 89.090408 | R20: ='3.2 Floor Finishes'!U54 -> 80805 | T20: =SUM(U20)/$C20 -> 0 | U20: ='3.2 Floor Finishes'!Z54 -> 0 | W20: =SUM(X20)/$C20 -> 0 | X20: ='3.2 Floor Finishes'!AE54 -> 0 | Z20: =SUM(AA20)/$C20 -> 0 | AA20: ='3.2 Floor Finishes'!AJ54 -> 0 | AC20: =SUM(AD20)/$C20 -> 0 | AD20: ='3.2 Floor Finishes'!AO54 -> 0 | AF20: =SUM(AG20)/$C20 -> 0 | AL20: =$I20*(1-#REF!) -> #REF! | AM20: =$I20*(1+#REF!) -> #REF! | AN20: =$I20*(1-#REF!) -> #REF! | AO20: =$I20*(1+#REF!) -> #REF!
A21: 3.3 | B21: Ceiling finishes | C21: ='Project Information - 3'!$C$16 -> 881 | D21: m2 | E21: =SUM(F21)/$C21 -> 483.14415 | F21: ='3.3 Ceiling finishes'!F54 -> 425650 | H21: =SUM(I21)/$C21 -> 531.62126 | I21: =AVERAGE(L21,O21,R21) -> 468358.33 | K21: =SUM(L21)/$C21 -> 449.60272 | L21: ='3.3 Ceiling finishes'!K54 -> 396100 | N21: =SUM(O21)/$C21 -> 597.41771 | O21: ='3.3 Ceiling finishes'!P54 -> 526325 | Q21: =SUM(R21)/$C21 -> 547.84336 | R21: ='3.3 Ceiling finishes'!U54 -> 482650 | T21: =SUM(U21)/$C21 -> 0 | U21: ='3.3 Ceiling finishes'!Z54 -> 0 | W21: =SUM(X21)/$C21 -> 0 | X21: ='3.3 Ceiling finishes'!AE54 -> 0 | Z21: =SUM(AA21)/$C21 -> 0 | AA21: ='3.3 Ceiling finishes'!AJ54 -> 0 | AC21: =SUM(AD21)/$C21 -> 0 | AD21: ='3.3 Ceiling finishes'!AO54 -> 0 | AF21: =SUM(AG21)/$C21 -> 0
A22: 4 | B22: Fittings, Furnishings & Equipment | F22: =SUM(F23) -> 67365 | I22: =SUM(I23) -> 67365 | L22: =SUM(L23) -> 67365 | O22: =SUM(O23) -> 67365 | R22: =SUM(R23) -> 67365 | U22: =SUM(U23) -> 0 | X22: =SUM(X23) -> 0 | AA22: =SUM(AA23) -> 0 | AD22: =SUM(AD23) -> 0 | AG22: =SUM(AG23) -> 0 | AJ22: =SUM(AJ23) -> 0
A23: 4.1 | B23: Fittings, furnishings and equipment | C23: ='Project Information - 3'!$C$17 -> 1 | D23: m2 | E23: =SUM(F23)/$C23 -> 67365 | F23: ='4.1 FF&E'!F54 -> 67365 | H23: =SUM(I23)/$C23 -> 67365 | I23: =AVERAGE(L23,O23,R23) -> 67365 | K23: =SUM(L23)/$C23 -> 67365 | L23: ='4.1 FF&E'!K54 -> 67365 | N23: =SUM(O23)/$C23 -> 67365 | O23: ='4.1 FF&E'!P54 -> 67365 | Q23: =SUM(R23)/$C23 -> 67365 | R23: ='4.1 FF&E'!U54 -> 67365 | T23: =SUM(U23)/$C23 -> 0 | U23: ='4.1 FF&E'!Z54 -> 0 | W23: =SUM(X23)/$C23 -> 0 | X23: ='4.1 FF&E'!AE54 -> 0 | Z23: =SUM(AA23)/$C23 -> 0 | AA23: ='4.1 FF&E'!AJ54 -> 0 | AC23: =SUM(AD23)/$C23 -> 0 | AD23: ='4.1 FF&E'!AO54 -> 0 | AF23: ='4.1 FF&E'!AR54 -> 0
A24: 5 | B24: Services | F24: =SUBTOTAL(9,F25:F27) -> 108430 | I24: =SUBTOTAL(9,I25:I27) -> 108430 | L24: =SUBTOTAL(9,L25:L27) -> 108430 | O24: =SUBTOTAL(9,O25:O27) -> 108430 | R24: 491679 | S24: =T24/'Project Information - 1'!$G$3 -> #DIV/0! | U24: 491679 | X24: 491679 | AA24: 491679 | AD24: 491679 | AG24: =SUBTOTAL(9,AG25:AG27) -> 0 | AJ24: =SUBTOTAL(9,AJ25:AJ27) -> 0
A25: 5.1 | B25: Sanitary installations | C25: ='Project Information - 3'!$C$18 -> 1 | D25: m2 | E25: =SUM(F25)/$C25 -> 69230 | F25: ='5.1 Sanitary installations'!F54 -> 69230 | H25: =SUM(I25)/$C25 -> 69230 | I25: =AVERAGE(L25,O25,R25) -> 69230 | K25: =SUM(L25)/$C25 -> 69230 | L25: ='5.1 Sanitary installations'!K54 -> 69230 | N25: =SUM(O25)/$C25 -> 69230 | O25: ='5.1 Sanitary installations'!P54 -> 69230 | Q25: =SUM(R25)/$C25 -> 69230 | R25: ='5.1 Sanitary installations'!U54 -> 69230 | T25: =SUM(U25)/$C25 -> 0 | U25: ='5.1 Sanitary installations'!Z54 -> 0 | W25: =SUM(X25)/$C25 -> 0 | X25: ='5.1 Sanitary installations'!AE54 -> 0 | Z25: =SUM(AA25)/$C25 -> 0 | AA25: ='5.1 Sanitary installations'!AJ54 -> 0 | AC25: =SUM(AD25)/$C25 -> 0 | AD25: ='5.1 Sanitary installations'!AO54 -> 0 | AF25: =SUM(AG25)/$C25 -> 0
A26: 5.2 | B26: Services equipment | C26: ='Project Information - 3'!$C$19 -> 1 | D26: m2 | E26: =SUM(F26)/$C26 -> 21600 | F26: ='5.2 Services equipment'!F54 -> 21600 | H26: =SUM(I26)/$C26 -> 21600 | I26: =AVERAGE(L26,O26,R26) -> 21600 | K26: =SUM(L26)/$C26 -> 21600 | L26: ='5.2 Services equipment'!K54 -> 21600 | N26: =SUM(O26)/$C26 -> 21600 | O26: ='5.2 Services equipment'!P54 -> 21600 | Q26: =SUM(R26)/$C26 -> 21600 | R26: ='5.2 Services equipment'!U54 -> 21600 | T26: =SUM(U26)/$C26 -> 0 | U26: ='5.2 Services equipment'!Z54 -> 0 | W26: =SUM(X26)/$C26 -> 0 | X26: ='5.2 Services equipment'!AE54 -> 0 | Z26: =SUM(AA26)/$C26 -> 0 | AA26: ='5.2 Services equipment'!AJ54 -> 0 | AC26: =SUM(AD26)/$C26 -> 0 | AD26: ='5.2 Services equipment'!AO54 -> 0 | AF26: =SUM(AG26)/$C26 -> 0
A27: 5.3 | B27: Electrical Installations | C27: ='Project Information - 3'!$C$20 -> 1 | D27: m2 | E27: =SUM(F27)/$C27 -> 17600 | F27: ='5.3 Electrical Installations'!F54 -> 17600 | H27: =SUM(I27)/$C27 -> 17600 | I27: =AVERAGE(L27,O27,R27) -> 17600 | K27: =SUM(L27)/$C27 -> 17600 | L27: ='5.3 Electrical Installations'!K54 -> 17600 | N27: =SUM(O27)/$C27 -> 17600 | O27: ='5.3 Electrical Installations'!P54 -> 17600 | Q27: =SUM(R27)/$C27 -> 17600 | R27: ='5.3 Electrical Installations'!U54 -> 17600 | T27: =SUM(U27)/$C27 -> 0 | U27: ='5.3 Electrical Installations'!Z54 -> 0 | W27: =SUM(X27)/$C27 -> 0 | X27: ='5.3 Electrical Installations'!AE54 -> 0 | Z27: =SUM(AA27)/$C27 -> 0 | AA27: ='5.3 Electrical Installations'!AJ54 -> 0 | AC27: =SUM(AD27)/$C27 -> 0 | AD27: ='5.3 Electrical Installations'!AO54 -> 0 | AF27: =SUM(AG27)/$C27 -> 0
A28: 5.4 | B28: Mechanical Installations | C28: ='Project Information - 3'!$C$21 -> 1 | D28: m2 | E28: =SUM(F28)/$C28 -> 18500 | F28: ='5.4 Mechanical Installations'!F54 -> 18500 | H28: =SUM(I28)/$C28 -> 18500 | I28: =AVERAGE(L28,O28,R28) -> 18500 | K28: =SUM(L28)/$C28 -> 18500 | L28: ='5.4 Mechanical Installations'!K54 -> 18500 | N28: =SUM(O28)/$C28 -> 18500 | O28: ='5.4 Mechanical Installations'!P54 -> 18500 | Q28: =SUM(R28)/$C28 -> 18500 | R28: ='5.4 Mechanical Installations'!U54 -> 18500 | T28: =SUM(U28)/$C28 -> 0 | U28: ='5.4 Mechanical Installations'!Z54 -> 0 | W28: =SUM(X28)/$C28 -> 0 | X28: ='5.4 Mechanical Installations'!AE54 -> 0 | Z28: =SUM(AA28)/$C28 -> 0 | AA28: ='5.4 Mechanical Installations'!AJ54 -> 0 | AC28: =SUM(AD28)/$C28 -> 0 | AD28: ='5.4 Mechanical Installations'!AO54 -> 0 | AF28: =SUM(AG28)/$C28 -> 0
A29: 5.5 | B29: Lift and conveyor installations | C29: ='Project Information - 3'!$C$22 -> 1 | D29: ='Project Information - 1'!H45 -> 0 | E29: =SUM(F29)/$C29 -> 11000 | F29: ='5.5 Lift & conveyor'!F54 -> 11000 | H29: =SUM(I29)/$C29 -> 11000 | I29: =AVERAGE(L29,O29,R29) -> 11000 | K29: =SUM(L29)/$C29 -> 11000 | L29: ='5.5 Lift & conveyor'!K54 -> 11000 | N29: =SUM(O29)/$C29 -> 11000 | O29: ='5.5 Lift & conveyor'!P54 -> 11000 | Q29: =SUM(R29)/$C29 -> 11000 | R29: ='5.5 Lift & conveyor'!U54 -> 11000 | T29: =SUM(U29)/$C29 -> 0 | U29: ='5.5 Lift & conveyor'!Z54 -> 0 | W29: =SUM(X29)/$C29 -> 0 | X29: ='5.5 Lift & conveyor'!AE54 -> 0 | Z29: =SUM(AA29)/$C29 -> 0 | AA29: ='5.5 Lift & conveyor'!AJ54 -> 0 | AC29: =SUM(AD29)/$C29 -> 0 | AD29: ='5.5 Lift & conveyor'!AO54 -> 0 | AF29: =SUM(AG29)/$C29 -> 0
A30: 5.6 | B30: Fire and lightning protection | C30: ='Project Information - 3'!$C$23 -> 1 | D30: m2 | E30: =SUM(F30)/$C30 -> 16400 | F30: ='5.6 Fire & lightning protection'!F54 -> 16400 | H30: =SUM(I30)/$C30 -> 16400 | I30: =AVERAGE(L30,O30,R30) -> 16400 | K30: =SUM(L30)/$C30 -> 16400 | L30: ='5.6 Fire & lightning protection'!K54 -> 16400 | N30: =SUM(O30)/$C30 -> 16400 | O30: ='5.6 Fire & lightning protection'!P54 -> 16400 | Q30: =SUM(R30)/$C30 -> 16400 | R30: ='5.6 Fire & lightning protection'!U54 -> 16400 | T30: =SUM(U30)/$C30 -> 0 | U30: ='5.6 Fire & lightning protection'!Z54 -> 0 | W30: =SUM(X30)/$C30 -> 0 | X30: ='5.6 Fire & lightning protection'!AE54 -> 0 | Z30: =SUM(AA30)/$C30 -> 0 | AA30: ='5.6 Fire & lightning protection'!AJ54 -> 0 | AC30: =SUM(AD30)/$C30 -> 0 | AD30: ='5.6 Fire & lightning protection'!AO54 -> 0 | AF30: =SUM(AG30)/$C30 -> 0
A31: 5.7 | B31: Communication, security and control systems | C31: ='Project Information - 3'!$C$24 -> 1 | D31: m2 | E31: =SUM(F31)/$C31 -> 20000 | F31: ='5.7 Communication security'!F54 -> 20000 | H31: =SUM(I31)/$C31 -> 20000 | I31: =AVERAGE(L31,O31,R31) -> 20000 | K31: =SUM(L31)/$C31 -> 20000 | L31: ='5.7 Communication security'!K54 -> 20000 | N31: =SUM(O31)/$C31 -> 20000 | O31: ='5.7 Communication security'!P54 -> 20000 | Q31: =SUM(R31)/$C31 -> 20000 | R31: ='5.7 Communication security'!U54 -> 20000 | T31: =SUM(U31)/$C31 -> 20000 | U31: ='5.7 Communication security'!Z54 -> 20000 | W31: =SUM(X31)/$C31 -> 30000 | X31: ='5.7 Communication security'!AE54 -> 30000 | Z31: =SUM(AA31)/$C31 -> 27500 | AA31: ='5.7 Communication security'!AJ54 -> 27500 | AC31: =SUM(AD31)/$C31 -> 50000 | AD31: ='5.7 Communication security'!AO54 -> 50000 | AF31: =SUM(AG31)/$C31 -> 0
A32: 5.8 | B32: Specialist installations | C32: ='Project Information - 3'!$C$25 -> 1 | D32: m2 | E32: =SUM(F32)/$C32 -> 20000 | F32: ='5.8 Specialist installations'!F54 -> 20000 | H32: =SUM(I32)/$C32 -> 20000 | I32: =AVERAGE(L32,O32,R32) -> 20000 | K32: =SUM(L32)/$C32 -> 20000 | L32: ='5.8 Specialist installations'!K54 -> 20000 | N32: =SUM(O32)/$C32 -> 20000 | O32: ='5.8 Specialist installations'!P54 -> 20000 | Q32: =SUM(R32)/$C32 -> 20000 | R32: ='5.8 Specialist installations'!U54 -> 20000 | T32: =SUM(U32)/$C32 -> 20000 | U32: ='5.8 Specialist installations'!Z54 -> 20000 | W32: =SUM(X32)/$C32 -> 30000 | X32: ='5.8 Specialist installations'!AE54 -> 30000 | Z32: =SUM(AA32)/$C32 -> 27500 | AA32: ='5.8 Specialist installations'!AJ54 -> 27500 | AC32: =SUM(AD32)/$C32 -> 50000 | AD32: ='5.8 Specialist installations'!AO54 -> 50000 | AF32: =SUM(AG32)/$C32 -> 0
A33: 5.9 | B33: BWIC with services | C33: ='Project Information - 3'!$C$26 -> 1 | D33: m2 | E33: =SUM(F33)/$C33 -> 20000 | F33: ='5.9 BWIC with services'!F54 -> 20000 | H33: =SUM(I33)/$C33 -> 20000 | I33: =AVERAGE(L33,O33,R33) -> 20000 | K33: =SUM(L33)/$C33 -> 20000 | L33: ='5.9 BWIC with services'!K54 -> 20000 | N33: =SUM(O33)/$C33 -> 20000 | O33: ='5.9 BWIC with services'!P54 -> 20000 | Q33: =SUM(R33)/$C33 -> 20000 | R33: ='5.9 BWIC with services'!U54 -> 20000 | T33: =SUM(U33)/$C33 -> 20000 | U33: ='5.9 BWIC with services'!Z54 -> 20000 | W33: =SUM(X33)/$C33 -> 30000 | X33: ='5.9 BWIC with services'!AE54 -> 30000 | Z33: =SUM(AA33)/$C33 -> 27500 | AA33: ='5.9 BWIC with services'!AJ54 -> 27500 | AC33: =SUM(AD33)/$C33 -> 50000 | AD33: ='5.9 BWIC with services'!AO54 -> 50000 | AF33: =SUM(AG33)/$C33 -> 0
A34: 5.1 | B34: Testing and commissioning of services | C34: ='Project Information - 3'!$C$27 -> 1 | D34: m2 | E34: =SUM(F34)/$C34 -> 20000 | F34: ='5.10 Testing & Commissioning'!F54 -> 20000 | H34: =SUM(I34)/$C34 -> 20000 | I34: =AVERAGE(L34,O34,R34) -> 20000 | K34: =SUM(L34)/$C34 -> 20000 | L34: ='5.10 Testing & Commissioning'!K54 -> 20000 | N34: =SUM(O34)/$C34 -> 20000 | O34: ='5.10 Testing & Commissioning'!P54 -> 20000 | Q34: =SUM(R34)/$C34 -> 20000 | R34: ='5.10 Testing & Commissioning'!U54 -> 20000 | T34: =SUM(U34)/$C34 -> 20000 | U34: ='5.10 Testing & Commissioning'!Z54 -> 20000 | W34: =SUM(X34)/$C34 -> 30000 | X34: ='5.10 Testing & Commissioning'!AE54 -> 30000 | Z34: =SUM(AA34)/$C34 -> 27500 | AA34: ='5.10 Testing & Commissioning'!AJ54 -> 27500 | AC34: =SUM(AD34)/$C34 -> 50000 | AD34: ='5.10 Testing & Commissioning'!AO54 -> 50000 | AF34: =SUM(AG34)/$C34 -> 0
A35: 6 | B35: Prefabricated buildings and building units | F35: =SUM(F36:F44) -> 500000 | I35: =SUM(I36:I44) -> 500000 | L35: =SUM(L36:L44) -> 500000 | O35: =SUM(O36:O44) -> 500000 | R35: =SUM(R36:R44) -> 1283358 | S35: =T35/'Project Information - 1'!$G$3 -> #DIV/0! | U35: =SUM(U36:U44) -> 1283358 | X35: =SUM(X36:X44) -> 1433358 | AA35: =SUM(AA36:AA44) -> 1395858 | AD35: =SUM(AD36:AD44) -> 1733358 | AG35: =SUM(AG36:AG44) -> 0 | AJ35: =SUM(AJ36:AJ44) -> 0
A36: 6.1 | B36: Prefabricated buildings and building units | C36: ='Project Information - 3'!$C$28 -> 1000 | D36: m2 | E36: =SUM(F36)/$C36 -> 20 | F36: ='6.1 Prefab buildings & units'!F54 -> 20000 | H36: =SUM(I36)/$C36 -> 20 | I36: =AVERAGE(L36,O36,R36) -> 20000 | K36: =SUM(L36)/$C36 -> 20 | L36: ='6.1 Prefab buildings & units'!K54 -> 20000 | N36: =SUM(O36)/$C36 -> 20 | O36: ='6.1 Prefab buildings & units'!P54 -> 20000 | Q36: =SUM(R36)/$C36 -> 20 | R36: ='6.1 Prefab buildings & units'!U54 -> 20000 | T36: =SUM(U36)/$C36 -> 20 | U36: ='6.1 Prefab buildings & units'!Z54 -> 20000 | W36: =SUM(X36)/$C36 -> 30 | X36: ='6.1 Prefab buildings & units'!AE54 -> 30000 | Z36: =SUM(AA36)/$C36 -> 27.5 | AA36: ='6.1 Prefab buildings & units'!AJ54 -> 27500 | AC36: =SUM(AD36)/$C36 -> 50 | AD36: ='6.1 Prefab buildings & units'!AO54 -> 50000 | AF36: =SUM(AG36)/$C36 -> 0
A37: 7 | B37: Work to existing buildings | F37: =SUM(F38:F46) -> 260000 | I37: =SUM(I38:I46) -> 260000 | L37: =SUM(L38:L46) -> 260000 | O37: =SUM(O38:O46) -> 260000 | R37: =SUM(R38:R46) -> 651679 | U37: =SUM(U38:U46) -> 651679 | X37: =SUM(X38:X46) -> 731679 | AA37: =SUM(AA38:AA46) -> 711679 | AD37: =SUM(AD38:AD46) -> 891679 | AG37: =SUM(AG38:AG46) -> 0 | AJ37: =SUM(AJ38:AJ46) -> 0
A38: 7.1 | B38: Minor demolition and alteration works | C38: ='Project Information - 3'!$C$29 -> 1000 | D38: m2 | E38: =SUM(F38)/$C38 -> 20 | F38: ='7.1 Minor demolition'!F54 -> 20000 | H38: =SUM(I38)/$C38 -> 20 | I38: =AVERAGE(L38,O38,R38) -> 20000 | K38: =SUM(L38)/$C38 -> 20 | L38: ='7.1 Minor demolition'!K54 -> 20000 | N38: =SUM(O38)/$C38 -> 20 | O38: ='7.1 Minor demolition'!P54 -> 20000 | Q38: =SUM(R38)/$C38 -> 20 | R38: ='7.1 Minor demolition'!U54 -> 20000 | T38: =SUM(U38)/$C38 -> 20 | U38: ='7.1 Minor demolition'!Z54 -> 20000 | W38: =SUM(X38)/$C38 -> 30 | X38: ='7.1 Minor demolition'!AE54 -> 30000 | Z38: =SUM(AA38)/$C38 -> 27.5 | AA38: ='7.1 Minor demolition'!AJ54 -> 27500 | AC38: =SUM(AD38)/$C38 -> 50 | AD38: ='7.1 Minor demolition'!AO54 -> 50000 | AF38: =SUM(AG38)/$C38 -> 0
A39: 7.2 | B39: repairs to existing services | C39: ='Project Information - 3'!$C$30 -> 1000 | D39: m2 | E39: =SUM(F39)/$C39 -> 20 | F39: ='7.2 Repairs to existing'!F54 -> 20000 | H39: =SUM(I39)/$C39 -> 20 | I39: =AVERAGE(L39,O39,R39) -> 20000 | K39: =SUM(L39)/$C39 -> 20 | L39: ='7.2 Repairs to existing'!K54 -> 20000 | N39: =SUM(O39)/$C39 -> 20 | O39: ='7.2 Repairs to existing'!P54 -> 20000 | Q39: =SUM(R39)/$C39 -> 20 | R39: ='7.2 Repairs to existing'!U54 -> 20000 | T39: =SUM(U39)/$C39 -> 20 | U39: ='7.2 Repairs to existing'!Z54 -> 20000 | W39: =SUM(X39)/$C39 -> 30 | X39: ='7.2 Repairs to existing'!AE54 -> 30000 | Z39: =SUM(AA39)/$C39 -> 27.5 | AA39: ='7.2 Repairs to existing'!AJ54 -> 27500 | AC39: =SUM(AD39)/$C39 -> 50 | AD39: ='7.2 Repairs to existing'!AO54 -> 50000 | AF39: =SUM(AG39)/$C39 -> 0
A40: 7.3 | B40: Damp proof courses / fungus and beetle eradication | C40: ='Project Information - 3'!$C$31 -> 1000 | D40: m2 | E40: =SUM(F40)/$C40 -> 20 | F40: ='7.3 Damp proof courses'!F54 -> 20000 | H40: =SUM(I40)/$C40 -> 20 | I40: =AVERAGE(L40,O40,R40) -> 20000 | K40: =SUM(L40)/$C40 -> 20 | L40: ='7.3 Damp proof courses'!K54 -> 20000 | N40: =SUM(O40)/$C40 -> 20 | O40: ='7.3 Damp proof courses'!P54 -> 20000 | Q40: =SUM(R40)/$C40 -> 20 | R40: ='7.3 Damp proof courses'!U54 -> 20000 | T40: =SUM(U40)/$C40 -> 20 | U40: ='7.3 Damp proof courses'!Z54 -> 20000 | W40: =SUM(X40)/$C40 -> 30 | X40: ='7.3 Damp proof courses'!AE54 -> 30000 | Z40: =SUM(AA40)/$C40 -> 27.5 | AA40: ='7.3 Damp proof courses'!AJ54 -> 27500 | AC40: =SUM(AD40)/$C40 -> 50 | AD40: ='7.3 Damp proof courses'!AO54 -> 50000 | AF40: =SUM(AG40)/$C40 -> 0
A41: 7.4 | B41: Façade retention | C41: ='Project Information - 3'!$C$32 -> 1000 | D41: m2 | E41: =SUM(F41)/$C41 -> 20 | F41: ='7.4 Facade retention'!F54 -> 20000 | H41: =SUM(I41)/$C41 -> 20 | I41: =AVERAGE(L41,O41,R41) -> 20000 | K41: =SUM(L41)/$C41 -> 20 | L41: ='7.4 Facade retention'!K54 -> 20000 | N41: =SUM(O41)/$C41 -> 20 | O41: ='7.4 Facade retention'!P54 -> 20000 | Q41: =SUM(R41)/$C41 -> 20 | R41: ='7.4 Facade retention'!U54 -> 20000 | T41: =SUM(U41)/$C41 -> 20 | U41: ='7.4 Facade retention'!Z54 -> 20000 | W41: =SUM(X41)/$C41 -> 30 | X41: ='7.4 Facade retention'!AE54 -> 30000 | Z41: =SUM(AA41)/$C41 -> 27.5 | AA41: ='7.4 Facade retention'!AJ54 -> 27500 | AC41: =SUM(AD41)/$C41 -> 50 | AD41: ='7.4 Facade retention'!AO54 -> 50000 | AF41: =SUM(AG41)/$C41 -> 0
A42: 7.5 | B42: Cleaning existing surfaces | C42: ='Project Information - 3'!$C$33 -> 1000 | D42: m2 | E42: =SUM(F42)/$C42 -> 20 | F42: ='7.5 Cleaning existing surfaces'!F54 -> 20000 | H42: =SUM(I42)/$C42 -> 20 | I42: =AVERAGE(L42,O42,R42) -> 20000 | K42: =SUM(L42)/$C42 -> 20 | L42: ='7.5 Cleaning existing surfaces'!K54 -> 20000 | N42: =SUM(O42)/$C42 -> 20 | O42: ='7.5 Cleaning existing surfaces'!P54 -> 20000 | Q42: =SUM(R42)/$C42 -> 20 | R42: ='7.5 Cleaning existing surfaces'!U54 -> 20000 | T42: =SUM(U42)/$C42 -> 20 | U42: ='7.5 Cleaning existing surfaces'!Z54 -> 20000 | W42: =SUM(X42)/$C42 -> 30 | X42: ='7.5 Cleaning existing surfaces'!AE54 -> 30000 | Z42: =SUM(AA42)/$C42 -> 27.5 | AA42: ='7.5 Cleaning existing surfaces'!AJ54 -> 27500 | AC42: =SUM(AD42)/$C42 -> 50 | AD42: ='7.5 Cleaning existing surfaces'!AO54 -> 50000 | AF42: =SUM(AG42)/$C42 -> 0
...

Sheet Adjustments
E3: =SUMMARY!E3 -> Sample Cost Plan - Elm Court Residential, Rev 01 | J3: =SUMMARY!K3 -> Ridgeway Construction | O3: =SUMMARY!N3 -> Brightstone Builders | T3: =SUMMARY!Q3 -> Kestrel Contractors | Y3: =SUMMARY!T3 -> INSERT CONTRACTOR 4 | AD3: =SUMMARY!W3 -> INSERT CONTRACTOR 5 | AI3: =SUMMARY!Z3 -> INSERT CONTRACTOR 6 | AN3: =SUMMARY!AC3 -> INSERT CONTRACTOR 7
A4: 3.1 | C4: {=MID(CELL("filename",B3),FIND("]",CELL("filename",B3))+1,255)} -> Adjustments | D4: Qty | E4: Unit | F4: Rate | G4: Total | I4: Qty | J4: Unit | K4: Rate | L4: Total | N4: Qty | O4: Unit | P4: Rate | Q4: Total | S4: Qty | T4: Unit | U4: Rate | V4: Total | X4: Qty | Y4: Unit | Z4: Rate | AA4: Total | AC4: Qty | AD4: Unit | AE4: Rate | AF4: Total | AH4: Qty | AI4: Unit | AJ4: Rate | AK4: Total | AM4: Qty | AN4: Unit | AO4: Rate | AP4: Total
B5: =IF(C5>0,IF(D5>0,MAX($B$3:B4)+1," ")," ") | G5: =IF(ISBLANK(D5),"",D5*F5) | L5: =IF(ISBLANK(I5),"",I5*K5) | Q5: =IF(ISBLANK(N5),"",N5*P5) | V5: =IF(ISBLANK(S5),"",S5*U5) | AA5: =IF(ISBLANK(X5),"",X5*Z5) | AF5: =IF(ISBLANK(AC5),"",AC5*AE5) | AK5: =IF(ISBLANK(AH5),"",AH5*AJ5) | AP5: =IF(ISBLANK(AM5),"",AM5*AO5)
A6: =IF(C6<>"",$A$4,"") -> 3.1 | B6: =IF(C6>0,IF(D6>0,MAX($B$3:B5)+1," ")," ") | C6: =C4 -> Adjustments | G6: =IF(ISBLANK(D6),"",D6*F6) | L6: =IF(ISBLANK(I6),"",I6*K6) | Q6: =IF(ISBLANK(N6),"",N6*P6) | V6: =IF(ISBLANK(S6),"",S6*U6) | AA6: =IF(ISBLANK(X6),"",X6*Z6) | AF6: =IF(ISBLANK(AC6),"",AC6*AE6) | AK6: =IF(ISBLANK(AH6),"",AH6*AJ6) | AP6: =IF(ISBLANK(AM6),"",AM6*AO6)
A7: =IF(C7<>"",$A$4,"") | B7: =IF(C7>0,IF(D7>0,MAX($B$3:B6)+1," ")," ") | G7: =IF(ISBLANK(D7),"",D7*F7) | L7: =IF(ISBLANK(I7),"",I7*K7) | Q7: =IF(ISBLANK(N7),"",N7*P7) | V7: =IF(ISBLANK(S7),"",S7*U7) | AA7: =IF(ISBLANK(X7),"",X7*Z7) | AF7: =IF(ISBLANK(AC7),"",AC7*AE7) | AK7: =IF(ISBLANK(AH7),"",AH7*AJ7) | AP7: =IF(ISBLANK(AM7),"",AM7*AO7)
A8: =IF(C8<>"",$A$4,"") -> 3.1 | B8: =IF(C8>0,IF(D8>0,MAX($B$5:B7)+1," ")," ") -> 1 | C8: Party wall works allowance | D8: 1 | E8: item | F8: 8500 | G8: =F8*D8 -> 8500 | J8: m2 | K8: 0 | L8: =K8*I8 -> 0 | O8: m2 | P8: 0 | Q8: =P8*N8 -> 0 | T8: m2 | U8: 0 | V8: =U8*S8 -> 0 | Y8: m2 | Z8: 0 | AA8: =Z8*X8 -> 0 | AD8: m2 | AE8: 0 | AF8: =AE8*AC8 -> 0 | AI8: m2 | AJ8: 0 | AK8: =AJ8*AH8 -> 0 | AN8: m2 | AO8: 0 | AP8: =AO8*AM8 -> 0
A9: =IF(C9<>"",$A$4,"")
A10: =IF(C10<>"",$A$4,"") -> 3.1 | B10: =IF(C10>0,IF(D10>0,MAX($B$5:B9)+1," ")," ") | C10: Adjustment 2 | E10: m2 | F10: 0 | G10: =F10*D10 -> 0 | J10: m2 | K10: 0 | L10: =K10*I10 -> 0 | O10: m2 | P10: 0 | Q10: =P10*N10 -> 0 | T10: m2 | U10: 0 | V10: =U10*S10 -> 0 | Y10: m2 | Z10: 0 | AA10: =Z10*X10 -> 0 | AD10: m2 | AE10: 0 | AF10: =AE10*AC10 -> 0 | AI10: m2 | AJ10: 0 | AK10: =AJ10*AH10 -> 0 | AN10: m2 | AO10: 0 | AP10: =AO10*AM10 -> 0
A11: =IF(C11<>"",$A$4,"")
A12: =IF(C12<>"",$A$4,"") -> 3.1 | B12: =IF(C12>0,IF(D12>0,MAX($B$5:B11)+1," ")," ") | C12: Adjustment 3 | E12: m2 | F12: 0 | G12: =F12*D12 -> 0 | J12: m2 | K12: 0 | L12: =K12*I12 -> 0 | O12: m2 | P12: 0 | Q12: =P12*N12 -> 0 | T12: m2 | U12: 0 | V12: =U12*S12 -> 0 | Y12: m2 | Z12: 0 | AA12: =Z12*X12 -> 0 | AD12: m2 | AE12: 0 | AF12: =AE12*AC12 -> 0 | AI12: m2 | AJ12: 0 | AK12: =AJ12*AH12 -> 0 | AN12: m2 | AO12: 0 | AP12: =AO12*AM12 -> 0
A13: =IF(C13<>"",$A$4,"")
A14: =IF(C14<>"",$A$4,"") -> 3.1 | B14: =IF(C14>0,IF(D14>0,MAX($B$5:B13)+1," ")," ") | C14: Adjustment 4 | E14: m2 | F14: 0 | G14: =F14*D14 -> 0 | J14: m2 | K14: 0 | L14: =K14*I14 -> 0 | O14: m2 | P14: 0 | Q14: =P14*N14 -> 0 | T14: m2 | U14: 0 | V14: =U14*S14 -> 0 | Y14: m2 | Z14: 0 | AA14: =Z14*X14 -> 0 | AD14: m2 | AE14: 0 | AF14: =AE14*AC14 -> 0 | AI14: m2 | AJ14: 0 | AK14: =AJ14*AH14 -> 0 | AN14: m2 | AO14: 0 | AP14: =AO14*AM14 -> 0
A15: =IF(C15<>"",$A$4,"") | B15: =IF(C15>0,IF(D15>0,MAX($B$3:B14)+1," ")," ") | G15: =IF(ISBLANK(D15),"",D15*F15) | L15: =IF(ISBLANK(I15),"",I15*K15) | Q15: =IF(ISBLANK(N15),"",N15*P15) | V15: =IF(ISBLANK(S15),"",S15*U15) | AA15: =IF(ISBLANK(X15),"",X15*Z15) | AF15: =IF(ISBLANK(AC15),"",AC15*AE15) | AK15: =IF(ISBLANK(AH15),"",AH15*AJ15) | AP15: =IF(ISBLANK(AM15),"",AM15*AO15)
A16: =IF(C16<>"",$A$4,"") -> 3.1 | B16: =IF(C16>0,IF(D16>0,MAX($B$5:B15)+1," ")," ") | C16: Adjustment 1 | E16: m2 | F16: 0 | G16: =F16*D16 -> 0 | J16: m2 | K16: 0 | L16: =K16*I16 -> 0 | O16: m2 | P16: 0 | Q16: =P16*N16 -> 0 | T16: m2 | U16: 0 | V16: =U16*S16 -> 0 | Y16: m2 | Z16: 0 | AA16: =Z16*X16 -> 0 | AD16: m2 | AE16: 0 | AF16: =AE16*AC16 -> 0 | AI16: m2 | AJ16: 0 | AK16: =AJ16*AH16 -> 0 | AN16: m2 | AO16: 0 | AP16: =AO16*AM16 -> 0
A17: =IF(C17<>"",$A$4,"")
A18: =IF(C18<>"",$A$4,"") -> 3.1 | B18: =IF(C18>0,IF(D18>0,MAX($B$5:B17)+1," ")," ") | C18: Adjustment 2 | E18: m2 | F18: 0 | G18: =F18*D18 -> 0 | J18: m2 | K18: 0 | L18: =K18*I18 -> 0 | O18: m2 | P18: 0 | Q18: =P18*N18 -> 0 | T18: m2 | U18: 0 | V18: =U18*S18 -> 0 | Y18: m2 | Z18: 0 | AA18: =Z18*X18 -> 0 | AD18: m2 | AE18: 0 | AF18: =AE18*AC18 -> 0 | AI18: m2 | AJ18: 0 | AK18: =AJ18*AH18 -> 0 | AN18: m2 | AO18: 0 | AP18: =AO18*AM18 -> 0
A19: =IF(C19<>"",$A$4,"")
A20: =IF(C20<>"",$A$4,"") -> 3.1 | B20: =IF(C20>0,IF(D20>0,MAX($B$5:B19)+1," ")," ") | C20: Adjustment 3 | E20: m2 | F20: 0 | G20: =F20*D20 -> 0 | J20: m2 | K20: 0 | L20: =K20*I20 -> 0 | O20: m2 | P20: 0 | Q20: =P20*N20 -> 0 | T20: m2 | U20: 0 | V20: =U20*S20 -> 0 | Y20: m2 | Z20: 0 | AA20: =Z20*X20 -> 0 | AD20: m2 | AE20: 0 | AF20: =AE20*AC20 -> 0 | AI20: m2 | AJ20: 0 | AK20: =AJ20*AH20 -> 0 | AN20: m2 | AO20: 0 | AP20: =AO20*AM20 -> 0
A21: =IF(C21<>"",$A$4,"")
A22: =IF(C22<>"",$A$4,"") -> 3.1 | B22: =IF(C22>0,IF(D22>0,MAX($B$5:B21)+1," ")," ") | C22: Adjustment 4 | E22: m2 | F22: 0 | G22: =F22*D22 -> 0 | J22: m2 | K22: 0 | L22: =K22*I22 -> 0 | O22: m2 | P22: 0 | Q22: =P22*N22 -> 0 | T22: m2 | U22: 0 | V22: =U22*S22 -> 0 | Y22: m2 | Z22: 0 | AA22: =Z22*X22 -> 0 | AD22: m2 | AE22: 0 | AF22: =AE22*AC22 -> 0 | AI22: m2 | AJ22: 0 | AK22: =AJ22*AH22 -> 0 | AN22: m2 | AO22: 0 | AP22: =AO22*AM22 -> 0
A23: =IF(C23<>"",$A$4,"") | B23: =IF(C23>0,IF(D23>0,MAX($B$3:B22)+1," ")," ") | G23: =IF(ISBLANK(D23),"",D23*F23) | L23: =IF(ISBLANK(I23),"",I23*K23) | Q23: =IF(ISBLANK(N23),"",N23*P23) | V23: =IF(ISBLANK(S23),"",S23*U23) | AA23: =IF(ISBLANK(X23),"",X23*Z23) | AF23: =IF(ISBLANK(AC23),"",AC23*AE23) | AK23: =IF(ISBLANK(AH23),"",AH23*AJ23) | AP23: =IF(ISBLANK(AM23),"",AM23*AO23)
A24: =IF(C24<>"",$A$4,"") -> 3.1 | B24: =IF(C24>0,IF(D24>0,MAX($B$5:B23)+1," ")," ") | C24: Adjustment 1 | E24: m2 | F24: 0 | G24: =F24*D24 -> 0 | J24: m2 | K24: 0 | L24: =K24*I24 -> 0 | O24: m2 | P24: 0 | Q24: =P24*N24 -> 0 | T24: m2 | U24: 0 | V24: =U24*S24 -> 0 | Y24: m2 | Z24: 0 | AA24: =Z24*X24 -> 0 | AD24: m2 | AE24: 0 | AF24: =AE24*AC24 -> 0 | AI24: m2 | AJ24: 0 | AK24: =AJ24*AH24 -> 0 | AN24: m2 | AO24: 0 | AP24: =AO24*AM24 -> 0
A25: =IF(C25<>"",$A$4,"")
A26: =IF(C26<>"",$A$4,"") -> 3.1 | B26: =IF(C26>0,IF(D26>0,MAX($B$5:B25)+1," ")," ") | C26: Adjustment 2 | E26: m2 | F26: 0 | G26: =F26*D26 -> 0 | J26: m2 | K26: 0 | L26: =K26*I26 -> 0 | O26: m2 | P26: 0 | Q26: =P26*N26 -> 0 | T26: m2 | U26: 0 | V26: =U26*S26 -> 0 | Y26: m2 | Z26: 0 | AA26: =Z26*X26 -> 0 | AD26: m2 | AE26: 0 | AF26: =AE26*AC26 -> 0 | AI26: m2 | AJ26: 0 | AK26: =AJ26*AH26 -> 0 | AN26: m2 | AO26: 0 | AP26: =AO26*AM26 -> 0
A27: =IF(C27<>"",$A$4,"")
A28: =IF(C28<>"",$A$4,"") -> 3.1 | B28: =IF(C28>0,IF(D28>0,MAX($B$5:B27)+1," ")," ") | C28: Adjustment 3 | E28: m2 | F28: 0 | G28: =F28*D28 -> 0 | J28: m2 | K28: 0 | L28: =K28*I28 -> 0 | O28: m2 | P28: 0 | Q28: =P28*N28 -> 0 | T28: m2 | U28: 0 | V28: =U28*S28 -> 0 | Y28: m2 | Z28: 0 | AA28: =Z28*X28 -> 0 | AD28: m2 | AE28: 0 | AF28: =AE28*AC28 -> 0 | AI28: m2 | AJ28: 0 | AK28: =AJ28*AH28 -> 0 | AN28: m2 | AO28: 0 | AP28: =AO28*AM28 -> 0
A29: =IF(C29<>"",$A$4,"")
A30: =IF(C30<>"",$A$4,"") -> 3.1 | B30: =IF(C30>0,IF(D30>0,MAX($B$5:B29)+1," ")," ") | C30: Adjustment 4 | E30: m2 | F30: 0 | G30: =F30*D30 -> 0 | J30: m2 | K30: 0 | L30: =K30*I30 -> 0 | O30: m2 | P30: 0 | Q30: =P30*N30 -> 0 | T30: m2 | U30: 0 | V30: =U30*S30 -> 0 | Y30: m2 | Z30: 0 | AA30: =Z30*X30 -> 0 | AD30: m2 | AE30: 0 | AF30: =AE30*AC30 -> 0 | AI30: m2 | AJ30: 0 | AK30: =AJ30*AH30 -> 0 | AN30: m2 | AO30: 0 | AP30: =AO30*AM30 -> 0
A31: =IF(C31<>"",$A$4,"") | B31: =IF(C31>0,IF(D31>0,MAX($B$3:B30)+1," ")," ") | G31: =IF(ISBLANK(D31),"",D31*F31) | L31: =IF(ISBLANK(I31),"",I31*K31) | Q31: =IF(ISBLANK(N31),"",N31*P31) | V31: =IF(ISBLANK(S31),"",S31*U31) | AA31: =IF(ISBLANK(X31),"",X31*Z31) | AF31: =IF(ISBLANK(AC31),"",AC31*AE31) | AK31: =IF(ISBLANK(AH31),"",AH31*AJ31) | AP31: =IF(ISBLANK(AM31),"",AM31*AO31)
A32: =IF(C32<>"",$A$4,"") -> 3.1 | B32: =IF(C32>0,IF(D32>0,MAX($B$5:B31)+1," ")," ") | C32: Adjustment 1 | E32: m2 | F32: 0 | G32: =F32*D32 -> 0 | J32: m2 | K32: 0 | L32: =K32*I32 -> 0 | O32: m2 | P32: 0 | Q32: =P32*N32 -> 0 | T32: m2 | U32: 0 | V32: =U32*S32 -> 0 | Y32: m2 | Z32: 0 | AA32: =Z32*X32 -> 0 | AD32: m2 | AE32: 0 | AF32: =AE32*AC32 -> 0 | AI32: m2 | AJ32: 0 | AK32: =AJ32*AH32 -> 0 | AN32: m2 | AO32: 0 | AP32: =AO32*AM32 -> 0
A33: =IF(C33<>"",$A$4,"")
A34: =IF(C34<>"",$A$4,"") -> 3.1 | B34: =IF(C34>0,IF(D34>0,MAX($B$5:B33)+1," ")," ") | C34: Adjustment 2 | E34: m2 | F34: 0 | G34: =F34*D34 -> 0 | J34: m2 | K34: 0 | L34: =K34*I34 -> 0 | O34: m2 | P34: 0 | Q34: =P34*N34 -> 0 | T34: m2 | U34: 0 | V34: =U34*S34 -> 0 | Y34: m2 | Z34: 0 | AA34: =Z34*X34 -> 0 | AD34: m2 | AE34: 0 | AF34: =AE34*AC34 -> 0 | AI34: m2 | AJ34: 0 | AK34: =AJ34*AH34 -> 0 | AN34: m2 | AO34: 0 | AP34: =AO34*AM34 -> 0
A35: =IF(C35<>"",$A$4,"")
A36: =IF(C36<>"",$A$4,"") -> 3.1 | B36: =IF(C36>0,IF(D36>0,MAX($B$5:B35)+1," ")," ") | C36: Adjustment 3 | E36: m2 | F36: 0 | G36: =F36*D36 -> 0 | J36: m2 | K36: 0 | L36: =K36*I36 -> 0 | O36: m2 | P36: 0 | Q36: =P36*N36 -> 0 | T36: m2 | U36: 0 | V36: =U36*S36 -> 0 | Y36: m2 | Z36: 0 | AA36: =Z36*X36 -> 0 | AD36: m2 | AE36: 0 | AF36: =AE36*AC36 -> 0 | AI36: m2 | AJ36: 0 | AK36: =AJ36*AH36 -> 0 | AN36: m2 | AO36: 0 | AP36: =AO36*AM36 -> 0
A37: =IF(C37<>"",$A$4,"")
A38: =IF(C38<>"",$A$4,"") -> 3.1 | B38: =IF(C38>0,IF(D38>0,MAX($B$5:B37)+1," ")," ") | C38: Adjustment 4 | E38: m2 | F38: 0 | G38: =F38*D38 -> 0 | J38: m2 | K38: 0 | L38: =K38*I38 -> 0 | O38: m2 | P38: 0 | Q38: =P38*N38 -> 0 | T38: m2 | U38: 0 | V38: =U38*S38 -> 0 | Y38: m2 | Z38: 0 | AA38: =Z38*X38 -> 0 | AD38: m2 | AE38: 0 | AF38: =AE38*AC38 -> 0 | AI38: m2 | AJ38: 0 | AK38: =AJ38*AH38 -> 0 | AN38: m2 | AO38: 0 | AP38: =AO38*AM38 -> 0
A39: =IF(C39<>"",$A$4,"") | B39: =IF(C39>0,IF(D39>0,MAX($B$3:B38)+1," ")," ") | G39: =IF(ISBLANK(D39),"",D39*F39) | L39: =IF(ISBLANK(I39),"",I39*K39) | Q39: =IF(ISBLANK(N39),"",N39*P39) | V39: =IF(ISBLANK(S39),"",S39*U39) | AA39: =IF(ISBLANK(X39),"",X39*Z39) | AF39: =IF(ISBLANK(AC39),"",AC39*AE39) | AK39: =IF(ISBLANK(AH39),"",AH39*AJ39) | AP39: =IF(ISBLANK(AM39),"",AM39*AO39)
A40: =IF(C40<>"",$A$4,"") -> 3.1 | B40: =IF(C40>0,IF(D40>0,MAX($B$5:B39)+1," ")," ") | C40: Adjustment 1 | E40: m2 | F40: 0 | G40: =F40*D40 -> 0 | J40: m2 | K40: 0 | L40: =K40*I40 -> 0 | O40: m2 | P40: 0 | Q40: =P40*N40 -> 0 | T40: m2 | U40: 0 | V40: =U40*S40 -> 0 | Y40: m2 | Z40: 0 | AA40: =Z40*X40 -> 0 | AD40: m2 | AE40: 0 | AF40: =AE40*AC40 -> 0 | AI40: m2 | AJ40: 0 | AK40: =AJ40*AH40 -> 0 | AN40: m2 | AO40: 0 | AP40: =AO40*AM40 -> 0
A41: =IF(C41<>"",$A$4,"")
A42: =IF(C42<>"",$A$4,"") -> 3.1 | B42: =IF(C42>0,IF(D42>0,MAX($B$5:B41)+1," ")," ") | C42: Adjustment 2 | E42: m2 | F42: 0 | G42: =F42*D42 -> 0 | J42: m2 | K42: 0 | L42: =K42*I42 -> 0 | O42: m2 | P42: 0 | Q42: =P42*N42 -> 0 | T42: m2 | U42: 0 | V42: =U42*S42 -> 0 | Y42: m2 | Z42: 0 | AA42: =Z42*X42 -> 0 | AD42: m2 | AE42: 0 | AF42: =AE42*AC42 -> 0 | AI42: m2 | AJ42: 0 | AK42: =AJ42*AH42 -> 0 | AN42: m2 | AO42: 0 | AP42: =AO42*AM42 -> 0
...

Sheet Frame - Proj 1
A2: Project 01 - Breakdown
B4: Order of Cost Estimate - Rev 00 | D4: Frame
C5: Qty | D5: Unit | E5: Rate | F5: Total
A6: =IF(B6>0,IF(C6>0,MAX($A$3:A5)+1," ")," ") | F6: =IF(ISBLANK(C6),"",C6*E6)
B7: Frame | F7: =IF(ISBLANK(C7),"",C7*E7)
F8: =IF(ISBLANK(C8),"",C8*E8)
A9: =IF(B9>0,IF(C9>0,MAX($A$3:A8)+1," ")," ") -> 1 | B9: Allowance for structural modifications to Glulam beams | C9: 1 | D9: Item | F9: =IF(ISBLANK(C9),"",C9*E9) -> 0
A10: =IF(B10>0,IF(C10>0,MAX($A$3:A9)+1," ")," ") -> 2 | B10: Extra over for varnishing | C10: 1 | D10: item | F10: =IF(ISBLANK(C10),"",C10*E10) -> 0
A11: =IF(B11>0,IF(C11>0,MAX($A$4:A9)+1," ")," ") | F11: =IF(ISBLANK(C11),"",C11*E11)
E12: Total | F12: =SUM(F6:F11) -> 0

Sheet 0.1 Demolition & alterations
B1: Return to ELEMENT INDEX
B2: Return to SUMMARY
C3: =SUMMARY!E3 -> Sample Cost Plan - Elm Court Residential, Rev 01 | H3: =SUMMARY!K3 -> Ridgeway Construction | M3: =SUMMARY!N3 -> Brightstone Builders | R3: =SUMMARY!Q3 -> Kestrel Contractors | W3: =SUMMARY!T3 -> INSERT CONTRACTOR 4 | AB3: =SUMMARY!W3 -> INSERT CONTRACTOR 5 | AG3: =SUMMARY!Z3 -> INSERT CONTRACTOR 6 | AL3: =SUMMARY!AC3 -> INSERT CONTRACTOR 7
B4: {=MID(CELL("filename",A3),FIND("]",CELL("filename",A3))+1,255)} -> 0.1 Demolition & alterations | C4: Qty | D4: Unit | E4: Rate | F4: Total | H4: Qty | I4: Unit | J4: Rate | K4: Total | M4: Qty | N4: Unit | O4: Rate | P4: Total | R4: Qty | S4: Unit | T4: Rate | U4: Total | W4: Qty | X4: Unit | Y4: Rate | Z4: Total | AB4: Qty | AC4: Unit | AD4: Rate | AE4: Total | AG4: Qty | AH4: Unit | AI4: Rate | AJ4: Total | AL4: Qty | AM4: Unit | AN4: Rate | AO4: Total
A5: =IF(B5>0,IF(C5>0,MAX($A$3:A4)+1," ")," ") | F5: =IF(ISBLANK(C5),"",C5*E5) | K5: =IF(ISBLANK(H5),"",H5*J5) | P5: =IF(ISBLANK(M5),"",M5*O5) | U5: =IF(ISBLANK(R5),"",R5*T5) | Z5: =IF(ISBLANK(W5),"",W5*Y5) | AE5: =IF(ISBLANK(AB5),"",AB5*AD5) | AJ5: =IF(ISBLANK(AG5),"",AG5*AI5) | AO5: =IF(ISBLANK(AL5),"",AL5*AN5)
A6: =IF(B6>0,IF(C6>0,MAX($A$3:A5)+1," ")," ") | B6: =B4 -> 0.1 Demolition & alterations | F6: =IF(ISBLANK(C6),"",C6*E6) | K6: =IF(ISBLANK(H6),"",H6*J6) | P6: =IF(ISBLANK(M6),"",M6*O6) | U6: =IF(ISBLANK(R6),"",R6*T6) | Z6: =IF(ISBLANK(W6),"",W6*Y6) | AE6: =IF(ISBLANK(AB6),"",AB6*AD6) | AJ6: =IF(ISBLANK(AG6),"",AG6*AI6) | AO6: =IF(ISBLANK(AL6),"",AL6*AN6)
A7: =IF(B7>0,IF(C7>0,MAX($A$3:A6)+1," ")," ") | F7: =IF(ISBLANK(C7),"",C7*E7) | K7: =IF(ISBLANK(H7),"",H7*J7) | P7: =IF(ISBLANK(M7),"",M7*O7) | U7: =IF(ISBLANK(R7),"",R7*T7) | Z7: =IF(ISBLANK(W7),"",W7*Y7) | AE7: =IF(ISBLANK(AB7),"",AB7*AD7) | AJ7: =IF(ISBLANK(AG7),"",AG7*AI7) | AO7: =IF(ISBLANK(AL7),"",AL7*AN7)
A8: =IF(B8>0,IF(C8>0,MAX($A$5:A7)+1," ")," ") -> 1 | B8: Site Clearance | C8: 1001 | D8: m2 | E8: 1.5 | F8: =IF(ISBLANK(C8),"",C8*E8) -> 1501.5 | H8: 1001 | I8: m2 | J8: 1 | K8: =IF(ISBLANK(H8),"",H8*J8) -> 1001 | M8: 1001 | N8: m2 | O8: 1.5 | P8: =IF(ISBLANK(M8),"",M8*O8) -> 1501.5 | R8: 1001 | S8: m2 | T8: 1.5 | U8: =IF(ISBLANK(R8),"",R8*T8) -> 1501.5 | X8: m2 | Z8: =IF(ISBLANK(W8),"",W8*Y8) | AC8: m2 | AE8: =IF(ISBLANK(AB8),"",AB8*AD8) | AH8: m2 | AJ8: =IF(ISBLANK(AG8),"",AG8*AI8) | AM8: m2 | AO8: =IF(ISBLANK(AL8),"",AL8*AN8)
A9: =IF(B9>0,IF(C9>0,MAX($A$5:A8)+1," ")," ")
A10: =IF(B10>0,IF(C10>0,MAX($A$5:A9)+1," ")," ") -> 2 | B10: Asbestos Removal | C10: 1001 | D10: m2 | E10: 25 | F10: =IF(ISBLANK(C10),"",C10*E10) -> 25025 | H10: 1001 | I10: m2 | J10: 20 | K10: =IF(ISBLANK(H10),"",H10*J10) -> 20020 | M10: 1001 | N10: m2 | O10: 35 | P10: =IF(ISBLANK(M10),"",M10*O10) -> 35035 | R10: 1001 | S10: m2 | T10: 50 | U10: =IF(ISBLANK(R10),"",R10*T10) -> 50050 | X10: m2 | Z10: =IF(ISBLANK(W10),"",W10*Y10) | AC10: m2 | AE10: =IF(ISBLANK(AB10),"",AB10*AD10) | AH10: m2 | AJ10: =IF(ISBLANK(AG10),"",AG10*AI10) | AM10: m2 | AO10: =IF(ISBLANK(AL10),"",AL10*AN10)
A11: =IF(B11>0,IF(C11>0,MAX($A$5:A10)+1," ")," ")
A12: =IF(B12>0,IF(C12>0,MAX($A$5:A11)+1," ")," ") -> 3 | B12: Soft Strip out of the existing building | C12: 1001 | D12: m2 | E12: 100 | F12: =IF(ISBLANK(C12),"",C12*E12) -> 100100 | H12: 1001 | I12: m2 | J12: 100 | K12: =IF(ISBLANK(H12),"",H12*J12) -> 100100 | M12: 1001 | N12: m2 | O12: 75 | P12: =IF(ISBLANK(M12),"",M12*O12) -> 75075 | R12: 1001 | S12: m2 | T12: 75 | U12: =IF(ISBLANK(R12),"",R12*T12) -> 75075 | X12: m2 | Z12: =IF(ISBLANK(W12),"",W12*Y12) | AC12: m2 | AE12: =IF(ISBLANK(AB12),"",AB12*AD12) | AH12: m2 | AJ12: =IF(ISBLANK(AG12),"",AG12*AI12) | AM12: m2 | AO12: =IF(ISBLANK(AL12),"",AL12*AN12)
A13: =IF(B13>0,IF(C13>0,MAX($A$5:A12)+1," ")," ")
A14: =IF(B14>0,IF(C14>0,MAX($A$5:A13)+1," ")," ") -> 4 | B14: Allowance for proping | C14: 10 | D14: m2 | E14: 100 | F14: =IF(ISBLANK(C14),"",C14*E14) -> 1000 | H14: 10 | I14: m2 | J14: 45 | K14: =IF(ISBLANK(H14),"",H14*J14) -> 450 | M14: 10 | N14: m2 | O14: 100 | P14: =IF(ISBLANK(M14),"",M14*O14) -> 1000 | R14: 10 | S14: m2 | T14: 100 | U14: =IF(ISBLANK(R14),"",R14*T14) -> 1000 | X14: m2 | Z14: =IF(ISBLANK(W14),"",W14*Y14) | AC14: m2 | AE14: =IF(ISBLANK(AB14),"",AB14*AD14) | AH14: m2 | AJ14: =IF(ISBLANK(AG14),"",AG14*AI14) | AM14: m2 | AO14: =IF(ISBLANK(AL14),"",AL14*AN14)
A15: =IF(B15>0,IF(C15>0,MAX($A$5:A14)+1," ")," ")
A16: =IF(B16>0,IF(C16>0,MAX($A$5:A15)+1," ")," ") -> 5 | B16: Allowance for temporary diversion works | C16: 10 | D16: m2 | E16: 100 | F16: =IF(ISBLANK(C16),"",C16*E16) -> 1000 | H16: 10 | I16: m2 | J16: 75 | K16: =IF(ISBLANK(H16),"",H16*J16) -> 750 | M16: 10 | N16: m2 | O16: 100 | P16: =IF(ISBLANK(M16),"",M16*O16) -> 1000 | R16: 10 | S16: m2 | T16: 100 | U16: =IF(ISBLANK(R16),"",R16*T16) -> 1000 | X16: m2 | Z16: =IF(ISBLANK(W16),"",W16*Y16) | AC16: m2 | AE16: =IF(ISBLANK(AB16),"",AB16*AD16) | AH16: m2 | AJ16: =IF(ISBLANK(AG16),"",AG16*AI16) | AM16: m2 | AO16: =IF(ISBLANK(AL16),"",AL16*AN16)
A17: =IF(B17>0,IF(C17>0,MAX($A$5:A16)+1," ")," ")
A18: =IF(B18>0,IF(C18>0,MAX($A$5:A17)+1," ")," ") -> 6 | B18: Allowance for site investigation works | C18: 10 | D18: m2 | E18: 100 | F18: =IF(ISBLANK(C18),"",C18*E18) -> 1000 | H18: 10 | I18: m2 | J18: 75 | K18: =IF(ISBLANK(H18),"",H18*J18) -> 750 | M18: 10 | N18: m2 | O18: 100 | P18: =IF(ISBLANK(M18),"",M18*O18) -> 1000 | R18: 10 | S18: m2 | T18: 100 | U18: =IF(ISBLANK(R18),"",R18*T18) -> 1000 | X18: m2 | Z18: =IF(ISBLANK(W18),"",W18*Y18) | AC18: m2 | AE18: =IF(ISBLANK(AB18),"",AB18*AD18) | AH18: m2 | AJ18: =IF(ISBLANK(AG18),"",AG18*AI18) | AM18: m2 | AO18: =IF(ISBLANK(AL18),"",AL18*AN18)
A19: =IF(B19>0,IF(C19>0,MAX($A$5:A18)+1," ")," ") | F19: =IF(ISBLANK(C19),"",C19*E19) | K19: =IF(ISBLANK(H19),"",H19*J19) | P19: =IF(ISBLANK(M19),"",M19*O19) | U19: =IF(ISBLANK(R19),"",R19*T19) | Z19: =IF(ISBLANK(W19),"",W19*Y19) | AE19: =IF(ISBLANK(AB19),"",AB19*AD19) | AJ19: =IF(ISBLANK(AG19),"",AG19*AI19) | AO19: =IF(ISBLANK(AL19),"",AL19*AN19)
A20: =IF(B20>0,IF(C20>0,MAX($A$5:A19)+1," ")," ") -> 7 | B20: Isolation of services | C20: 1 | D20: item | E20: 2500 | F20: =IF(ISBLANK(C20),"",C20*E20) -> 2500 | H20: 1 | I20: item | J20: 5000 | K20: =IF(ISBLANK(H20),"",H20*J20) -> 5000 | M20: 1 | N20: item | O20: 5000 | P20: =IF(ISBLANK(M20),"",M20*O20) -> 5000 | R20: 1 | S20: item | T20: 2500 | U20: =IF(ISBLANK(R20),"",R20*T20) -> 2500 | X20: item | Z20: =IF(ISBLANK(W20),"",W20*Y20) | AC20: item | AE20: =IF(ISBLANK(AB20),"",AB20*AD20) | AH20: item | AJ20: =IF(ISBLANK(AG20),"",AG20*AI20) | AM20: item | AO20: =IF(ISBLANK(AL20),"",AL20*AN20)
A21: =IF(B21>0,IF(C21>0,MAX($A$5:A20)+1," ")," ") | F21: =IF(ISBLANK(C21),"",C21*E21) | K21: =IF(ISBLANK(H21),"",H21*J21) | P21: =IF(ISBLANK(M21),"",M21*O21) | U21: =IF(ISBLANK(R21),"",R21*T21) | Z21: =IF(ISBLANK(W21),"",W21*Y21) | AE21: =IF(ISBLANK(AB21),"",AB21*AD21) | AJ21: =IF(ISBLANK(AG21),"",AG21*AI21) | AO21: =IF(ISBLANK(AL21),"",AL21*AN21)
A22: =IF(B22>0,IF(C22>0,MAX($A$5:A21)+1," ")," ") -> 8 | B22: Removal of suspended ceilings | C22: 1 | D22: item/m2 | E22: 500 | F22: =IF(ISBLANK(C22),"",C22*E22) -> 500 | H22: 1 | I22: item/m2 | J22: 500 | K22: =IF(ISBLANK(H22),"",H22*J22) -> 500 | M22: 1 | N22: item/m2 | O22: 500 | P22: =IF(ISBLANK(M22),"",M22*O22) -> 500 | R22: 1 | S22: item/m2 | T22: 500 | U22: =IF(ISBLANK(R22),"",R22*T22) -> 500 | X22: item/m2 | Z22: =IF(ISBLANK(W22),"",W22*Y22) | AC22: item/m2 | AE22: =IF(ISBLANK(AB22),"",AB22*AD22) | AH22: item/m2 | AJ22: =IF(ISBLANK(AG22),"",AG22*AI22) | AM22: item/m2 | AO22: =IF(ISBLANK(AL22),"",AL22*AN22)
A23: =IF(B23>0,IF(C23>0,MAX($A$5:A22)+1," ")," ") | F23: =IF(ISBLANK(C23),"",C23*E23) | K23: =IF(ISBLANK(H23),"",H23*J23) | P23: =IF(ISBLANK(M23),"",M23*O23) | U23: =IF(ISBLANK(R23),"",R23*T23) | Z23: =IF(ISBLANK(W23),"",W23*Y23) | AE23: =IF(ISBLANK(AB23),"",AB23*AD23) | AJ23: =IF(ISBLANK(AG23),"",AG23*AI23) | AO23: =IF(ISBLANK(AL23),"",AL23*AN23)
A24: =IF(B24>0,IF(C24>0,MAX($A$5:A23)+1," ")," ") -> 9 | B24: Removal of floor finishes | C24: 1 | D24: item/m2 | E24: 150 | F24: =IF(ISBLANK(C24),"",C24*E24) -> 150 | H24: 1 | I24: item/m2 | J24: 150 | K24: =IF(ISBLANK(H24),"",H24*J24) -> 150 | M24: 1 | N24: item/m2 | O24: 150 | P24: =IF(ISBLANK(M24),"",M24*O24) -> 150 | R24: 1 | S24: item/m2 | T24: 150 | U24: =IF(ISBLANK(R24),"",R24*T24) -> 150 | X24: item/m2 | Z24: =IF(ISBLANK(W24),"",W24*Y24) | AC24: item/m2 | AE24: =IF(ISBLANK(AB24),"",AB24*AD24) | AH24: item/m2 | AJ24: =IF(ISBLANK(AG24),"",AG24*AI24) | AM24: item/m2 | AO24: =IF(ISBLANK(AL24),"",AL24*AN24)
A25: =IF(B25>0,IF(C25>0,MAX($A$5:A24)+1," ")," ") | F25: =IF(ISBLANK(C25),"",C25*E25) | K25: =IF(ISBLANK(H25),"",H25*J25) | P25: =IF(ISBLANK(M25),"",M25*O25) | U25: =IF(ISBLANK(R25),"",R25*T25) | Z25: =IF(ISBLANK(W25),"",W25*Y25) | AE25: =IF(ISBLANK(AB25),"",AB25*AD25) | AJ25: =IF(ISBLANK(AG25),"",AG25*AI25) | AO25: =IF(ISBLANK(AL25),"",AL25*AN25)
A26: =IF(B26>0,IF(C26>0,MAX($A$5:A25)+1," ")," ") -> 10 | B26: Removal of wall finishes | C26: 1 | D26: item/m2 | E26: 500 | F26: =IF(ISBLANK(C26),"",C26*E26) -> 500 | H26: 1 | I26: item/m2 | J26: 500 | K26: =IF(ISBLANK(H26),"",H26*J26) -> 500 | M26: 1 | N26: item/m2 | O26: 500 | P26: =IF(ISBLANK(M26),"",M26*O26) -> 500 | R26: 1 | S26: item/m2 | T26: 500 | U26: =IF(ISBLANK(R26),"",R26*T26) -> 500 | X26: item/m2 | Z26: =IF(ISBLANK(W26),"",W26*Y26) | AC26: item/m2 | AE26: =IF(ISBLANK(AB26),"",AB26*AD26) | AH26: item/m2 | AJ26: =IF(ISBLANK(AG26),"",AG26*AI26) | AM26: item/m2 | AO26: =IF(ISBLANK(AL26),"",AL26*AN26)
A27: =IF(B27>0,IF(C27>0,MAX($A$5:A26)+1," ")," ") | F27: =IF(ISBLANK(C27),"",C27*E27) | K27: =IF(ISBLANK(H27),"",H27*J27) | P27: =IF(ISBLANK(M27),"",M27*O27) | U27: =IF(ISBLANK(R27),"",R27*T27) | Z27: =IF(ISBLANK(W27),"",W27*Y27) | AE27: =IF(ISBLANK(AB27),"",AB27*AD27) | AJ27: =IF(ISBLANK(AG27),"",AG27*AI27) | AO27: =IF(ISBLANK(AL27),"",AL27*AN27)
A28: =IF(B28>0,IF(C28>0,MAX($A$5:A27)+1," ")," ") -> 11 | B28: Removal of internal doors | C28: 25 | D28: nr | E28: 75 | F28: =IF(ISBLANK(C28),"",C28*E28) -> 1875 | H28: 25 | I28: nr | J28: 75 | K28: =IF(ISBLANK(H28),"",H28*J28) -> 1875 | M28: 25 | N28: nr | O28: 75 | P28: =IF(ISBLANK(M28),"",M28*O28) -> 1875 | R28: 25 | S28: nr | T28: 75 | U28: =IF(ISBLANK(R28),"",R28*T28) -> 1875 | X28: nr | Z28: =IF(ISBLANK(W28),"",W28*Y28) | AC28: nr | AE28: =IF(ISBLANK(AB28),"",AB28*AD28) | AH28: nr | AJ28: =IF(ISBLANK(AG28),"",AG28*AI28) | AM28: nr | AO28: =IF(ISBLANK(AL28),"",AL28*AN28)
A29: =IF(B29>0,IF(C29>0,MAX($A$5:A28)+1," ")," ") | F29: =IF(ISBLANK(C29),"",C29*E29) | K29: =IF(ISBLANK(H29),"",H29*J29) | P29: =IF(ISBLANK(M29),"",M29*O29) | U29: =IF(ISBLANK(R29),"",R29*T29) | Z29: =IF(ISBLANK(W29),"",W29*Y29) | AE29: =IF(ISBLANK(AB29),"",AB29*AD29) | AJ29: =IF(ISBLANK(AG29),"",AG29*AI29) | AO29: =IF(ISBLANK(AL29),"",AL29*AN29)
